Workbook

Sheet Title Page

Sheet S1. Metadata incl Categories
A1: Broad Category | B1: Sub-category | C1: Includ. | D1: Field | E1: Meaning | F1: Unit | G1: Source | H1: Reference
A2: Environmental | B2: Habitat | C2: N | D2: Perimeter | E2: Species range perimeter | F2: km | G2: IUCN Red List (IUCN) | H2: International Union for Conservation of Nature (IUCN). The IUCN Red List of Threatened Species. Version 2024-2. (2024).
A3: Environmental | B3: Habitat | C3: N | D3: Perimeter_p | E3: Species range perimeter / range area | F3: km2 / area | G3: IUCN
A4: Environmental | B4: Habitat | C4: N | D4: North_Limit | E4: Species range northern limit | F4: Decimal Degrees | G4: IUCN
A5: Environmental | B5: Habitat | C5: Y | D5: South_Limit | E5: Species range southern limit | F5: Decimal Degrees | G5: IUCN
A6: Environmental | B6: Habitat | C6: Y | D6: East_Limit | E6: Species range eastern limit | F6: Decimal Degrees | G6: IUCN
A7: Socioeconomic | B7: Impoundments | C7: N | D7: Dams | E7: Total existing dams within range | F7: Count | G7: Global Dam Watch (GDW) | H7: Lehner, B. et al. The Global Dam Watch database of river barrier and reservoir information for large-scale applications. Sci. Data 11, 1069 (2024).
A8: Socioeconomic | B8: Impoundments | C8: Y | D8: Dams_p | E8: Total existing dams / range area | F8: Count | G8: GDW
A9: Socioeconomic | B9: Impoundments | C9: N | D9: CAB_Dams_p | E9: Total catchment areas blocked | F9: km2 | G9: GDW
A10: Socioeconomic | B10: Impoundments | C10: Y | D10: CAB_Dams_p | E10: Total catchment areas blocked / range area | F10: Proportion | G10: GDW
A11: Socioeconomic | B11: Impoundments | C11: N | D11: DB_Dams | E11: Total discharge blocked | F11: m3/sec | G11: GDW
A12: Socioeconomic | B12: Impoundments | C12: Y | D12: DB_Dams_p | E12: Total discharge blocked / range area | F12: m3/sec / area | G12: GDW
A13: Socioeconomic | B13: Impoundments | C13: N | D13: RA_Dams | E13: Total reservoir area in range | F13: km2 | G13: GDW
A14: Socioeconomic | B14: Impoundments | C14: Y | D14: RA_Dams_p | E14: Total reservoir area in range / range area | F14: Proportion | G14: GDW
A15: Socioeconomic | B15: Economy | C15: Y | D15: GDPslope | E15: Avg. annual change in GDP | F15: Million Dollars | G15: World Bank | H15: The World Bank. World Development Indicators. World Bank Open Data Catalog. Washington, D.C., United States. (2020).
A16: Socioeconomic | B16: Economy | C16: Y | D16: GDPpercent | E16: Avg. annual percent change in GDP | F16: Percent | G16: World Bank
A17: Socioeconomic | B17: Economy | C17: N | D17: PCslope | E17: Avg. annual change in GDP per capita | F17: Million Dollars | G17: World Bank
A18: Socioeconomic | B18: Economy | C18: N | D18: PCpercent | E18: Avg. annual percent change in GDP per capita | F18: Percent | G18: World Bank
A19: Socioeconomic | B19: Economy | C19: Y | D19: EarlyPC | E19: Early GDP per capita (1960s) | F19: Million USD | G19: World Bank
A20: Socioeconomic | B20: Development | C20: Y | D20: PDslope | E20: Avg. annual change in population density 2000-2020 | F20: Population/km2 | G20: WorldPop | H20: Lloyd, C. T. et al. Global spatio-temporally harmonised datasets for producing high-resolution gridded population distribution datasets. Big Earth Data 3, 108–139 (2019).
A21: Socioeconomic | B21: Development | C21: Y | D21: PDpercent | E21: Avg. annual percent change in population density | F21: Percent Change | G21: WorldPop
A22: Socioeconomic | B22: Development | C22: N | D22: LatestPD | E22: Population density 2020 | F22: Population/km2 | G22: WorldPop
A23: Socioeconomic | B23: Development | C23: N | D23: EarlyPD | E23: Population density 2000 | F23: Population/km2 | G23: WorldPop
A24: Environmental | B24: Climate | C24: N | D24: bio_1 | E24: Historic Annual Mean Temperature | F24: °C | G24: WorldClim v2.1 - Historic | H24: Fick, S. E. & Hijmans, R. J. WorldClim 2: new 1-km spatial resolution climate surfaces for global land areas. Int. J. Climatol. 37, 4302–4315 (2017).
A25: Environmental | B25: Climate | C25: N | D25: bio_2 | E25: Historic Mean Diurnal Temperature Range | F25: °C | G25: WorldClim v2.1 - Historic
A26: Environmental | B26: Climate | C26: N | D26: bio_3 | E26: Historic Isothermality | F26: °C (Ratio) | G26: WorldClim v2.1 - Historic
A27: Environmental | B27: Climate | C27: Y | D27: bio_4 | E27: Historic Temperature Seasonality | F27: °C (SD) | G27: WorldClim v2.1 - Historic
A28: Environmental | B28: Climate | C28: N | D28: bio_5 | E28: Historic Max Temperature of Warmest Month | F28: °C | G28: WorldClim v2.1 - Historic
A29: Environmental | B29: Climate | C29: N | D29: bio_ 6 | E29: Historic Min Temperature of Coldest Month | F29: °C | G29: WorldClim v2.1 - Historic
A30: Environmental | B30: Climate | C30: N | D30: bio_7 | E30: Historic Temperature Annual Range | F30: °C | G30: WorldClim v2.1 - Historic
A31: Environmental | B31: Climate | C31: Y | D31: bio_8 | E31: Historic Mean Temperature of Wettest Quarter | F31: °C | G31: WorldClim v2.1 - Historic
A32: Environmental | B32: Climate | C32: N | D32: bio_9 | E32: Historic Mean Temperature of Driest Quarter | F32: °C | G32: WorldClim v2.1 - Historic
A33: Environmental | B33: Climate | C33: N | D33: bio_10 | E33: Historic Mean Temperature of Warmest Quarter | F33: °C | G33: WorldClim v2.1 - Historic
A34: Environmental | B34: Climate | C34: N | D34: bio_11 | E34: Historic Mean Temperature of Coldest Quarter | F34: °C | G34: WorldClim v2.1 - Historic
A35: Environmental | B35: Climate | C35: N | D35: bio_12 | E35: Historic Annual Precipitation | F35: mm | G35: WorldClim v2.1 - Historic
A36: Environmental | B36: Climate | C36: N | D36: bio_13 | E36: Historic Precipitation of Wettest Month | F36: mm | G36: WorldClim v2.1 - Historic
... A42: Environmental | B42: Climate | C42: Y | D42: bio_19 | E42: Historic Precipitation of Coldest Quarter | F42: mm | G42: WorldClim v2.1 - Historic
A43: Species | B43: Physiology | C43: N | D43: pH_Range | E43: maximum – minimum pH | F43: standard units | G43: Fish Base | H43: Froese, R. & Pauly, D. FishBase. World Wide Web electronic publication, version (04/2025). (2025).
A44: Species | B44: Physiology | C44: N | D44: pHMin | E44: Minimum pH | F44: standard units | G44: FishBase
A45: Species | B45: Physiology | C45: N | D45: pHMax | E45: Maximum pH | F45: standard units | G45: FishBase
...

Sheet S2. Summary Ordinal Forest
A1: Confusion matrix
C2: Reference
C3: LC | D3: NT | E3: VU | F3: EN | G3: CR
A4: Predictions | B4: LC | C4: 1443 | D4: 113 | E4: 130 | F4: 97 | G4: 35
B5: NT | C5: 0 | D5: 1 | E5: 0 | F5: 0 | G5: 0
B6: VU | C6: 10 | D6: 2 | E6: 29 | F6: 10 | G6: 4
B7: EN | C7: 12 | D7: 21 | E7: 47 | F7: 97 | G7: 45
B8: CR | C8: 2 | D8: 1 | E8: 4 | F8: 7 | G8: 22
A10: Predictive performance metrics by class
B12: Sensitivity | C12: Specificity | D12: Pos Pred Value | E12: Neg Pred Value | F12: Precision | G12: Recall | H12: F1 | I12: Prevalence | J12: Detection Rate | K12: Detection Prevalence | L12: Balanced Accuracy
A13: LC | B13: 0.98364008 | C13: 0.43609023 | D13: 0.79372937 | E13: 0.92356688 | F13: 0.79372937 | G13: 0.98364008 | H13: 0.87853881 | I13: 0.6880863 | J13: 0.67682927 | K13: 0.85272045 | L13: 0.70986515
A14: NT | B14: 0.007246377 | C14: 1 | D14: 1 | E14: 0.93571093 | F14: 1 | G14: 0.007246377 | H14: 0.014388489 | I14: 0.064727955 | J14: 0.000469043 | K14: 0.000469043 | L14: 0.50362319
A15: VU | B15: 0.13809524 | C15: 0.98647242 | D15: 0.52727273 | E15: 0.91285508 | F15: 0.52727273 | G15: 0.13809524 | H15: 0.21886792 | I15: 0.098499062 | J15: 0.013602251 | K15: 0.025797373 | L15: 0.56228383
A16: EN | B16: 0.45971564 | C16: 0.93492972 | D16: 0.43693694 | E16: 0.94031414 | F16: 0.43693694 | G16: 0.45971564 | H16: 0.44803695 | I16: 0.098968105 | J16: 0.045497186 | K16: 0.10412758 | L16: 0.69732268
A17: CR | B17: 0.20754717 | C17: 0.99308983 | D17: 0.61111111 | E17: 0.95992366 | F17: 0.61111111 | G17: 0.20754717 | H17: 0.30985915 | I17: 0.049718574 | J17: 0.010318949 | K17: 0.016885553 | L17: 0.6003185
A19: Performance metrics and variability in tuning
A20: Macro-averaged mean absolute error (macroMAE) was used to select the optimal model using the smallest value.
A21: Values averaged across 5-fold cross-validation tests and 5 repeats.
A22: The final value used for the model was mtry = 42.
A24: mtry | B24: macroMAE | C24: macroMSE | D24: V3 | E24: Accuracy | F24: Kappa | G24: macroMAESD | H24: macroMSESD | I24: V3SD | J24: AccuracySD | K24: KappaSD
A25: 42 | B25: 0.12954463 | C25: 0.078729126 | D25: 0.86958457 | E25: 0.73701065 | F25: 0.32762145 | G25: 0.0034024895 | H25: 0.0030905003 | I25: 0.0032158148 | J25: 0.0046882034 | K25: 0.013660564 | L25: final model
A26: 49 | B26: 0.12967937 | C26: 0.078803813 | D26: 0.86960834 | E26: 0.73656535 | F26: 0.32843331 | G26: 0.0034385606 | H26: 0.0030511908 | I26: 0.0031799172 | J26: 0.0051480361 | K26: 0.01470445
A27: 43 | B27: 0.12977898 | C27: 0.079051271 | D27: 0.86956074 | E27: 0.73712749 | F27: 0.32808635 | G27: 0.0038147109 | H27: 0.0033685204 | I27: 0.0035485127 | J27: 0.0052732829 | K27: 0.015676076
A28: 51 | B28: 0.12983148 | C28: 0.07892958 | D28: 0.86970942 | E28: 0.73651866 | F28: 0.32966571 | G28: 0.0035573967 | H28: 0.0030443684 | I28: 0.0034790063 | J28: 0.0055594219 | K28: 0.01572949
A29: 48 | B29: 0.12986089 | C29: 0.078948744 | D29: 0.86975084 | E29: 0.73649512 | F29: 0.32817975 | G29: 0.0037645149 | H29: 0.0032990337 | I29: 0.0034668697 | J29: 0.0053284025 | K29: 0.015329148
A30: 44 | B30: 0.1298727 | C30: 0.07901029 | D30: 0.86936119 | E30: 0.73672928 | F30: 0.32744558 | G30: 0.0034436137 | H30: 0.0031111659 | I30: 0.0032964719 | J30: 0.0049331676 | K30: 0.014638007
A31: 47 | B31: 0.12989613 | C31: 0.079016219 | D31: 0.86958611 | E31: 0.7365655 | F31: 0.32778987 | G31: 0.0032288884 | H31: 0.0029074736 | I31: 0.0032476882 | J31: 0.0050588097 | K31: 0.0150034
A32: 46 | B32: 0.12999557 | C32: 0.079160999 | D32: 0.86932923 | E32: 0.73677616 | F32: 0.32816097 | G32: 0.0033897328 | H32: 0.0030803323 | I32: 0.0032489174 | J32: 0.0050576643 | K32: 0.014139806
A33: 45 | B33: 0.13007177 | C33: 0.079200582 | D33: 0.869425 | E33: 0.73656525 | F33: 0.32701344 | G33: 0.0034351187 | H33: 0.0031778382 | I33: 0.0033766099 | J33: 0.0049811501 | K33: 0.014086259
A34: 50 | B34: 0.13007738 | C34: 0.07905838 | D34: 0.86964172 | E34: 0.73598 | F34: 0.32802257 | G34: 0.0032594382 | H34: 0.0028514204 | I34: 0.0031686091 | J34: 0.0050722962 | K34: 0.013699271
A35: 41 | B35: 0.13012439 | C35: 0.079204927 | D35: 0.86906777 | E35: 0.73651858 | F35: 0.32517207 | G35: 0.0034537637 | H35: 0.0031584363 | I35: 0.0034111985 | J35: 0.0050326567 | K35: 0.014490811
A36: 52 | B36: 0.13017112 | C36: 0.079111107 | D36: 0.86968447 | E36: 0.7358159 | F36: 0.32784006 | G36: 0.0032001238 | H36: 0.0027557191 | I36: 0.0033357524 | J36: 0.0052355137 | K36: 0.015103202
A37: 37 | B37: 0.13019486 | C37: 0.079371938 | D37: 0.86883932 | E37: 0.73670564 | F37: 0.32436197 | G37: 0.0036152229 | H37: 0.0033503345 | I37: 0.0032279594 | J37: 0.0052369789 | K37: 0.015732915
... A57: 20 | B57: 0.13311125 | C57: 0.082118585 | D57: 0.86507479 | E57: 0.73433994 | F57: 0.30557557 | G57: 0.0032378498 | H57: 0.0030281786 | I57: 0.0028290134 | J57: 0.0044786546 | K57: 0.0133535

Sheet S3. Summary Random Forest
A1: Confusion matrix | C1: n test dataset | H1: percentage test dataset
C2: Reference | H2: Reference
C3: Imperiled | D3: Non-imperiled | H3: Imperiled | I3: Non-imperiled
A4: Predicted | B4: Imperiled | C4: 359 | D4: 83 | F4: Predicted | G4: Imperiled | H4: =C4/(C4+D4)*100 -> 81.221719 | I4: =D4/(C4+D4)*100 -> 18.778281
B5: Non-imperiled | C5: 168 | D5: 1522 | G5: Non-imperiled | H5: =C5/(C5+D5)*100 -> 9.9408284 | I5: =D5/(C5+D5)*100 -> 90.059172
A7: Average performance metrics and variability in tuning
A8: Precision-recall AUC was used to select the optimal model using the largest value.
A9: Values averaged across 5-fold cross-validation tests and 5 repeats
A10: The final value used for the model was mtry = 10.
A12: mtry | B12: V1 | C12: AUC | D12: Precision | E12: Recall | F12: F | G12: ROC | H12: Sens | I12: Spec | J12: Accuracy | K12: Kappa | L12: V1SD | M12: AUCSD | N12: PrecisionSD | O12: RecallSD | P12: FSD | Q12: ROCSD | R12: SensSD | S12: SpecSD | T12: AccuracySD | U12: KappaSD
A13: 10 | B13: 0.72759942 | C13: 0.81708915 | D13: 0.79632661 | E13: 0.67013479 | F13: 0.72759942 | G13: 0.92905598 | H13: 0.67013479 | I13: 0.94353307 | J13: 0.87587294 | K13: 0.64801309 | L13: 0.016987354 | M13: 0.022530808 | N13: 0.01947043 | O13: 0.021601665 | P13: 0.016987354 | Q13: 0.0078325686 | R13: 0.021601665 | S13: 0.006472413 | T13: 0.0073607863 | U13: 0.021422476 | V13: final model
A14: 9 | B14: 0.72703581 | C14: 0.81693933 | D14: 0.79723438 | E14: 0.66852364 | F14: 0.72703581 | G14: 0.92914569 | H14: 0.66852364 | I14: 0.944 | J14: 0.87582583 | K14: 0.6474908 | L14: 0.016349002 | M14: 0.022571327 | N14: 0.017926156 | O14: 0.021242115 | P14: 0.016349002 | Q14: 0.0077997174 | R14: 0.021242115 | S14: 0.0059626674 | T14: 0.0069210272 | U14: 0.020449723
A15: 11 | B15: 0.72784489 | C15: 0.81665412 | D15: 0.79623387 | E15: 0.6706076 | F15: 0.72784489 | G15: 0.92886533 | H15: 0.6706076 | I15: 0.94347082 | J15: 0.87594313 | K15: 0.64828894 | L15: 0.016047697 | M15: 0.022222232 | N15: 0.01793766 | O15: 0.021060966 | P15: 0.016047697 | Q15: 0.0077543389 | R15: 0.021060966 | S15: 0.0060608864 | T15: 0.0068330221 | U15: 0.020103556
A16: 12 | B16: 0.72837257 | C16: 0.81657472 | D16: 0.79472585 | E16: 0.67259453 | F16: 0.72837257 | G16: 0.92884441 | H16: 0.67259453 | I16: 0.94275486 | J16: 0.87589617 | K16: 0.64868895 | L16: 0.016859276 | M16: 0.022458482 | N16: 0.019951835 | O16: 0.021271455 | P16: 0.016859276 | Q16: 0.0079078357 | R16: 0.021271455 | S16: 0.0067323047 | T16: 0.007407687 | U16: 0.021354831
A17: 13 | B17: 0.72868354 | C17: 0.81633899 | D17: 0.79432855 | E17: 0.67335283 | F17: 0.72868354 | G17: 0.92852529 | H17: 0.67335283 | I17: 0.94256809 | J17: 0.87594311 | K17: 0.64899502 | L17: 0.017544395 | M17: 0.022471121 | N17: 0.020389665 | O17: 0.020912903 | P17: 0.017544395 | Q17: 0.0078064242 | R17: 0.020912903 | S17: 0.0067019511 | T17: 0.0077869661 | U17: 0.022331772
A18: 8 | B18: 0.7269572 | C18: 0.81618251 | D18: 0.79920298 | E18: 0.66701018 | F18: 0.7269572 | G18: 0.92904789 | H18: 0.66701018 | I18: 0.94480934 | J18: 0.8760602 | K18: 0.64765611 | L18: 0.016865231 | M18: 0.022446117 | N18: 0.018189718 | O18: 0.021686869 | P18: 0.016865231 | Q18: 0.0078693933 | R18: 0.021686869 | S18: 0.0059772076 | T18: 0.0071412192 | U18: 0.021109506
A19: 7 | B19: 0.72655959 | C19: 0.81579397 | D19: 0.80026871 | E19: 0.66559242 | F19: 0.72655959 | G19: 0.92903108 | H19: 0.66559242 | I19: 0.94527626 | J19: 0.87606037 | K19: 0.64732154 | L19: 0.016071087 | M19: 0.022519924 | N19: 0.018649878 | O19: 0.020314033 | P19: 0.016071087 | Q19: 0.0076962929 | R19: 0.020314033 | S19: 0.0061388234 | T19: 0.0069393758 | U19: 0.020233453
A20: 14 | B20: 0.72611638 | C20: 0.81569712 | D20: 0.790628 | E20: 0.67164891 | F20: 0.72611638 | G20: 0.92839393 | H20: 0.67164891 | I20: 0.94141634 | J20: 0.87465469 | K20: 0.64556261 | L20: 0.015690458 | M20: 0.022329349 | N20: 0.017796177 | O20: 0.020282703 | P20: 0.015690458 | Q20: 0.0077309881 | R20: 0.020282703 | S20: 0.0061215349 | T20: 0.0068028804 | U20: 0.019772158
A21: 16 | B21: 0.72740918 | C21: 0.81559324 | D21: 0.79075166 | E21: 0.67372951 | F21: 0.72740918 | G21: 0.92818324 | H21: 0.67372951 | I21: 0.94129183 | J21: 0.87507616 | K21: 0.64706655 | L21: 0.015656894 | M21: 0.022493709 | N21: 0.017631582 | O21: 0.019599464 | P21: 0.015656894 | Q21: 0.0078024942 | R21: 0.019599464 | S21: 0.0059440176 | T21: 0.006842005 | U21: 0.019807997
A22: 6 | B22: 0.72698509 | C22: 0.81548835 | D22: 0.80439198 | E22: 0.66351069 | F22: 0.72698509 | G22: 0.92898822 | H22: 0.66351069 | I22: 0.94683268 | J22: 0.87671624 | K22: 0.64833273 | L22: 0.017309515 | M22: 0.02313536 | N22: 0.020224052 | O22: 0.021511163 | P22: 0.017309515 | Q22: 0.0078287933 | R22: 0.021511163 | S22: 0.006586956 | T22: 0.0074962386 | U22: 0.021817355
A23: 15 | B23: 0.72893931 | C23: 0.81522136 | D23: 0.79256838 | E23: 0.67505675 | F23: 0.72893931 | G23: 0.92829455 | H23: 0.67505675 | I23: 0.94182101 | J23: 0.87580253 | K23: 0.64907351 | L23: 0.016119081 | M23: 0.022104552 | N23: 0.017686969 | O23: 0.020554704 | P23: 0.016119081 | Q23: 0.0078719122 | R23: 0.020554704 | S23: 0.0059491097 | T23: 0.0069564526 | U23: 0.020308464
A24: 17 | B24: 0.7275232 | C24: 0.81513906 | D24: 0.78988997 | E24: 0.67458349 | F24: 0.7275232 | G24: 0.92798976 | H24: 0.67458349 | I24: 0.94088716 | J24: 0.87498262 | K24: 0.6470737 | L24: 0.015277155 | M24: 0.022606429 | N24: 0.018325609 | O24: 0.019304794 | P24: 0.015277155 | Q24: 0.0077911393 | R24: 0.019304794 | S24: 0.0063757845 | T24: 0.0067976824 | U24: 0.019419445
A25: 20 | B25: 0.72843353 | C25: 0.81469459 | D25: 0.78913725 | E25: 0.67666611 | F25: 0.72843353 | G25: 0.92759875 | H25: 0.67666611 | I25: 0.94045136 | J25: 0.87517007 | K25: 0.64802625 | L25: 0.015522735 | M25: 0.02232233 | N25: 0.018164844 | O25: 0.019092824 | P25: 0.015522735 | Q25: 0.0077704616 | R25: 0.019092824 | S25: 0.0061609803 | T25: 0.006908497 | U25: 0.019760754
... A31: 2 | B31: 0.70445076 | C31: 0.80605758 | D31: 0.8233775 | E31: 0.61599296 | F31: 0.70445076 | G31: 0.92601338 | H31: 0.61599296 | I31: 0.95642023 | J31: 0.87217189 | K31: 0.62508446 | L31: 0.019355145 | M31: 0.024465186 | N31: 0.022741701 | O31: 0.024027623 | P31: 0.019355145 | Q31: 0.0076078827 | R31: 0.024027623 | S31: 0.0065841972 | T31: 0.0077140174 | U31: 0.023655357

Sheet S4. Variable Importance
A1: Metadata | E1: VIMs binary model | J1: VIMs ordinal model
A2: Variable | B2: Description | C2: Category | D2: Subcategory | E2: AUC loss | F2: MDA Imperiled | G2: MDA Nonimperiled | H2: MDBA | I2: Gini | J2: ER | K2: RPS | L2: MAE | M2: MSE | P2: Category | Q2: AUC loss sum | R2: AUC loss percent
A3: Class_count_p | B3: Geomorphic classes / sqkm | C3: Environmental | D3: Habitat | E3: 89.445121 | F3: 103.36566 | G3: 75.52458 | H3: 103.14586 | I3: 359.21674 | J3: 0.027831688 | K3: 0.091217897 | L3: 0.089342248 | M3: 0.28546535 | P3: Environmental | Q3: =SUMIF(C:C,P3,E:E) -> 861.91438 | R3: =Q3/($Q$3+$Q$4+$Q$5)*100 -> 59.608869
A4: order | B4: Taxonomic order | C4: Species | D4: Taxonomic | E4: 69.976157 | F4: 88.131875 | G4: 51.82044 | H4: 81.717986 | I4: 204.37772 | J4: 0.040103364 | K4: 0.094156147 | L4: 0.11752924 | M4: 0.36067728 | P4: Species | Q4: =SUMIF(C:C,P4,E:E) -> 134.71947 | R4: =Q4/($Q$3+$Q$4+$Q$5)*100 -> 9.3170219
A5: Stream_pow | B5: Avg. total stream power (kW/m2) | C5: Environmental | D5: Hydrology | E5: 59.988547 | F5: 66.989949 | G5: 52.987145 | H5: 70.624048 | I5: 160.95643 | J5: 0.003432453 | K5: 0.007558238 | L5: 0.008769394 | M5: 0.024054547 | P5: Socioeconomic | Q5: =SUMIF(C:C,P5,E:E) -> 449.31606 | R5: =Q5/($Q$3+$Q$4+$Q$5)*100 -> 31.074109
A6: GDPpercent | B6: Avg. annual percent change in GDP | C6: Socioeconomic | D6: Economy | E6: 49.790409 | F6: 55.272835 | G6: 44.307984 | H6: 56.418205 | I6: 184.1039 | J6: 0.026379285 | K6: 0.068985465 | L6: 0.08245633 | M6: 0.25930426
A7: South_Limit | B7: Range southern limit (ºLat.) | C7: Environmental | D7: Habitat | E7: 46.24129 | F7: 40.370018 | G7: 52.112562 | H7: 56.713264 | I7: 117.52232 | J7: 0.014420036 | K7: 0.035469445 | L7: 0.043516502 | M7: 0.13415409
A8: Class_phys | B8: Physio-climatic sub-class mode | C8: Environmental | D8: Habitat | E8: 45.836777 | F8: 57.896642 | G8: 33.776912 | H8: 55.436723 | I8: 103.08228 | J8: 0.012237928 | K8: 0.033047732 | L8: 0.039516078 | M8: 0.12652149
A9: LC_PermanentWater | B9: Permanent water cover (%) | C9: Environmental | D9: Habitat | E9: 42.681933 | F9: 34.368312 | G9: 50.995554 | H9: 57.891542 | I9: 104.16235 | J9: 0.002770031 | K9: 0.007215134 | L9: 0.008637589 | M9: 0.026989706
A10: East_Limit | B10: Range eastern limit (ºLong.) | C10: Environmental | D10: Habitat | E10: 40.889297 | F10: 30.395712 | G10: 51.382883 | H10: 53.261578 | I10: 93.066555 | J10: 0.006514274 | K10: 0.016972403 | L10: 0.019240582 | M10: 0.058773639
A11: na_count | B11: Count of empty attributes | C11: Socioeconomic | D11: Knowledge | E11: 40.77039 | F11: 25.629269 | G11: 55.911511 | H11: 59.090199 | I11: 81.856859 | J11: 0.006013372 | K11: 0.016334676 | L11: 0.018422159 | M11: 0.058086809
A12: Protected_Percent | B12: Range Area Protection (%) | C12: Socioeconomic | D12: Conservation | E12: 38.94999 | F12: 36.493067 | G12: 41.406913 | H12: 47.805389 | I12: 85.0049 | J12: 0.002114825 | K12: 0.005213322 | L12: 0.006678765 | M12: 0.021102833
A13: hfp_2009 | B13: Human-footprint index in 2009 | C13: Socioeconomic | D13: Footprint | E13: 38.937334 | F13: 35.096706 | G13: 42.777962 | H13: 51.323285 | I13: 72.116153 | J13: 0.018956808 | K13: 0.045110098 | L13: 0.053111748 | M13: 0.15590364
A14: bio_8 | B14: Wettest quarter mean temp. (ºC) | C14: Environmental | D14: Climate | E14: 37.247818 | F14: 30.561678 | G14: 43.933958 | H14: 49.756528 | I14: 73.36455 | J14: 0.002804839 | K14: 0.006488904 | L14: 0.008010612 | M14: 0.024524037
A15: Log_Q_avg | B15: Long-term avg. discharge (log10) | C15: Environmental | D15: Hydrology | E15: 35.114545 | F15: 24.769554 | G15: 45.459535 | H15: 52.514199 | I15: 68.349934 | J15: 0.001385546 | K15: 0.003794377 | L15: 0.003991935 | M15: 0.012871272
A16: bio_18 | B16: Warmest quarter precipitation (mm) | C16: Environmental | D16: Climate | E16: 34.976113 | F16: 29.740183 | G16: 40.212042 | H16: 51.019432 | I16: 62.135894 | J16: 0.001452404 | K16: 0.003834624 | L16: 0.004288231 | M16: 0.013005837
A17: EarlyPC | B17: Early per capita GDP (1960s) | C17: Socioeconomic | D17: Economy | E17: 34.787852 | F17: 38.683012 | G17: 30.892691 | H17: 40.262761 | I17: 62.190319 | J17: 0.011569988 | K17: 0.027193911 | L17: 0.030358909 | M17: 0.084951502
... A54: Class_geom | B54: Geomorphic sub-class mode | C54: Environmental | D54: Habitat | E54: 0.42429365 | F54: 0.5716014 | G54: 0.2769859 | H54: 0.50664741 | I54: 1.4081989 | J54: 4.46e-06 | K54: 7.92e-06 | L54: 1.95e-05 | M54: 2.76e-05

Sheet S5. Partial Dependence
A1: *ordered by importance based on precision-recall AUC (loss)
A2: **colored rows are variables mapped in Figures 3 and 4
A3: Variable importance | C3: Metadata | I3: Results by variable in binary classification model
A4: AUC loss | B4: Rank* | C4: Variable | D4: Category | E4: Subcategory | F4: Meaning | G4: Source | H4: Unit | I4: Partial Dependence | J4: Description | K4: Interpretation
A5: =VLOOKUP(C5,'S4. Variable Importance'!A:M,5,FALSE) -> 89.445121 | B5: 1 | C5: Class_count_p | D5: Environmental | E5: Habitat | F5: Count of different classes of geomorphic sub-classification / range area | G5: GloRic | H5: count / km2 | I5: #VALUE! | J5: Log increase of imperilment probability with area-adjusted count of geomorphic classes | K5: Species presently distributed in fragmented range patches show a higher heterogeneity of geomorphic classes per sqk of range area. The opposite pattern is observed when this variable is not adjusted based on range area, for which the model shows a decreasing likelihood of imperilment with increasing geomorphic diversity.
A6: =VLOOKUP(C6,'S4. Variable Importance'!A:M,5,FALSE) -> 69.976157 | B6: 2 | C6: Order | D6: Species | E6: Taxonomy | F6: Taxonomic order | G6: FishBase | H6: categorical | I6: #VALUE!
A7: =VLOOKUP(C7,'S4. Variable Importance'!A:M,5,FALSE) -> 59.988547 | B7: 3 | C7: Stream_pow | D7: Environmental | E7: Hydrology | F7: Total stream power | G7: GloRic | H7: kW/m2 | I7: #VALUE! | J7: Asymptote curve showing inverse relationship between stream power and imperilment probability. Highest risk close to zero and sharp decrease towards 1, consistently low >2 | K7: stream power is a key environmental attribute influenced by precipitation, drainage areas, and discharge, as well as channel structure, topographic relief, and the availability of lentic habitats (e.g., wetlands, lakes, and reservoirs). Thus, low stream powers may be associated with drier regions, small basins, and or lower availability of free-flowing lotic environments.
A8: =VLOOKUP(C8,'S4. Variable Importance'!A:M,5,FALSE) -> 49.790409 | B8: 4 | C8: GDPpercent | D8: Social | E8: Economy | F8: Avg. annual percent change in GDP | G8: World Bank | H8: Percent | I8: #VALUE! | J8: Stepwise increase of imperilment probability with faster GDP growth (avg yearly %). Negative GDP values show the lowest probability, with a sharp increase >0.5% growth, moderate risk around 2-4%, and the highest imperilment probability for countries growing >4% per year | K8: Rapidly growing economies tend to have higher exploitation rates of natural resources, and start dedicating more resources towards population assessments and conservation, while the opposite may be evident in recessing economies. Undeveloped idea: There may also be traces of a "lag" in assessments from past disturbances and population declines, as developing countries start adopting UN/IUCN standards.
A9: =VLOOKUP(C9,'S4. Variable Importance'!A:M,5,FALSE) -> 45.836777 | B9: 5 | C9: Class_phys | D9: Environmental | E9: Habitat | F9: Mode of classes of physio-climatic sub-classification | G9: GloRiC | H9: categorical | I9: #VALUE! | J9: slightly higher imperilment probability for classes 311, 322, 212, 312 (high temps, low CMIs); slightly lower for classes 131, 122, 112 (low temps); with the rest ranging in between. GloRiC key available at: https://data.hydrosheds.org/file/technical-documentation/GloRiC_TechDoc_v10.pdf | K9: imperilment more prevalent at dryer, hotter regions compared to colder regions (dry and moist)
A10: =VLOOKUP(C10,'S4. Variable Importance'!A:M,5,FALSE) -> 42.681933 | B10: 6 | C10: LC_PermanentWater | D10: Environmental | E10: Habitat | F10: Cover type percentage | G10: Copernicus - PROBA-V | H10: Percent | I10: #VALUE! | J10: asymptote, highest imperilment probability with very low availability of permanent water bodies, sharp decrease and stable at low probabilities >0.5% | K10: imperilment is significantly more prevalent at regions with low availability of medium-to-large water bodies (e.g., lakes, reservoirs, ponds, mainstem rivers)
A11: =VLOOKUP(C11,'S4. Variable Importance'!A:M,5,FALSE) -> 40.889297 | B11: 7 | C11: East_Limit | D11: Environmental | E11: Habitat | F11: Species range eastern limit | G11: IUCN | H11: Decimal Degrees | I11: #VALUE! | J11: Roughly V-shaped, with highest risk west of 100º W, followed by a sharp decrease until 40ºW, followed by a sharp increase towards Greenwich meridian, and remaining high towards the East.
A12: =VLOOKUP(C12,'S4. Variable Importance'!A:M,5,FALSE) -> 40.77039 | B12: 8 | C12: na_count | D12: Social | E12: Knowledge | F12: Knowledge gaps | G12: FishBase + IUCN | H12: count | I12: #VALUE! | J12: highest at low values, lowest at moderate values, and moderately-low at highest na_count values | K12: species with the most information most likely to be classified as imperiled (moderate increase in imperilment risk for species with more unknown attributes), non-imperiled species tended to have moderately-low levels of information
A13: =VLOOKUP(C13,'S4. Variable Importance'!A:M,5,FALSE) -> 38.94999 | B13: 9 | C13: Protected_Percent | D13: Social | E13: Conservation | F13: percent of area protected within species range | G13: WDPA | H13: Percent | I13: #VALUE! | J13: asymptote, highest risk of imperilment at very low percents (<3%) of protected areas but sharply decreasing to lowest risk until 15%, and slowly and slightly increasing above 20%
A14: =VLOOKUP(C14,'S4. Variable Importance'!A:M,5,FALSE) -> 38.937334 | B14: 10 | C14: hfp_2009 | D14: Social | E14: Footprint | F14: Human-footprint index in 2009 | G14: Dryad | H14: Index | I14: #VALUE! | J14: positive linear relationship of imperilment probability with human footprint | K14: anthropic disturbances from various types can drive population decline and species imperilment
A15: =VLOOKUP(C15,'S4. Variable Importance'!A:M,5,FALSE) -> 37.247818 | B15: 11 | C15: bio_8 | D15: Environmental | E15: Climate | F15: Historic Mean Temperature of Wettest Quarter | G15: Wordclim 2.1 - Historic | H15: °C | I15: #VALUE! | J15: moderate risk >21ºC, decreasing until ~25ºC, then sharply increasing and remaining high >28ºC
A16: =VLOOKUP(C16,'S4. Variable Importance'!A:M,5,FALSE) -> 35.114545 | B16: 12 | C16: Log_Q_avg | D16: Environmental | E16: Hydrology | F16: log10 of long-term average discharge | G16: GloRic | H16: m3/sec | I16: #VALUE! | J16: J-shaped with valley at moderate discharges, and peak at highest discharges | K16: highest and lowest flows more associated with imperilment than moderate discharges
A17: =VLOOKUP(C17,'S4. Variable Importance'!A:M,5,FALSE) -> 34.976113 | B17: 13 | C17: bio_18 | D17: Environmental | E17: Climate | F17: Historic Precipitation of Warmest Quarter | G17: Wordclim 2.1 - Historic | H17: mm | I17: #VALUE! | J17: asymptote, highest risk when precipitation close to 0 mm, sharply dropping until ~200 mm, then low, trophing at 500 mm, then slight increase towards higher precipitation
A18: =VLOOKUP(C18,'S4. Variable Importance'!A:M,5,FALSE) -> 34.787852 | B18: 14 | C18: EarlyPC | D18: Social | E18: Economy | F18: Early per capita GDP (1960s) | G18: World Bank | H18: Million Dollars | I18: #VALUE!
A19: =VLOOKUP(C19,'S4. Variable Importance'!A:M,5,FALSE) -> 34.676848 | B19: 15 | C19: bio_19 | D19: Environmental | E19: Climate | F19: Historic Precipitation of Coldest Quarter | G19: Wordclim 2.1 - Historic | H19: mm | I19: #VALUE! | J19: highest just above 0, then drop and back up to moderate asymptote with step increase at ~800
A20: =VLOOKUP(C20,'S4. Variable Importance'!A:M,5,FALSE) -> 34.468445 | B20: 16 | C20: LC_SeasonalWater | D20: Environmental | E20: Habitat | F20: Cover type percentage | G20: Copernicus - PROBA-V | H20: Percent | I20: #VALUE!
A21: =VLOOKUP(C21,'S4. Variable Importance'!A:M,5,FALSE) -> 33.13189 | B21: 17 | C21: bio_16 | D21: Environmental | E21: Climate | F21: Historic Precipitation of Wettest Quarter | G21: Wordclim 2.1 - Historic | H21: mm | I21: #VALUE! | J21: U shaped, lowest between 500-1000
A22: =VLOOKUP(C22,'S4. Variable Importance'!A:M,5,FALSE) -> 32.214592 | B22: 18 | C22: bio_4 | D22: Environmental | E22: Climate | F22: Historic Temperature Seasonality | G22: Wordclim 2.1 - Historic | H22: °C (SD) | I22: #VALUE! | J22: L-ish shaped with highest probability of imperilment at regions with extremely low temperature seasonality, but sharply decreasing with trough at ~50, then slowly increasing with seasonality
A23: =VLOOKUP(C23,'S4. Variable Importance'!A:M,5,FALSE) -> 31.820813 | B23: 19 | C23: LC_Tree | D23: Environmental | E23: Habitat | F23: Cover type percentage | G23: Copernicus - PROBA-V | H23: Percent | I23: #VALUE! | J23: ushaped, lowest 25-65
A24: =VLOOKUP(C24,'S4. Variable Importance'!A:M,5,FALSE) -> 31.730096 | B24: 20 | C24: LC_Shrub | D24: Environmental | E24: Habitat | F24: Cover type percentage | G24: Copernicus - PROBA-V | H24: Percent | I24: #VALUE! | J24: lowest just above 0, then increasing with increasing shrub cover | K24: endangerment increases with shrub cover dominance
A25: =VLOOKUP(C25,'S4. Variable Importance'!A:M,5,FALSE) -> 31.730038 | B25: 21 | C25: CMI_indx | D25: Environmental | E25: Climate | F25: Mean reach climate moisture index | G25: GloRic, Global-PET, and WorldClim | H25: index | I25: #VALUE! | J25: U shaped, lowest around 0 | K25: lowest risk at intermediate climate moisture indexes (balanced precipitation and evapotransporation)
A26: =VLOOKUP(C26,'S4. Variable Importance'!A:M,5,FALSE) -> 31.56804 | B26: 22 | C26: Log_Q_var | D26: Environmental | E26: Hydrology | F26: Flow regime variability as log10 of maximum monthly avg. / long term avg. discharge | G26: GloRic | H26: index | I26: #VALUE! | J26: u-shaped, lowest between 0.2 and 0.4 | K26: endangerment risk highest at lowest flows and highest flows
A27: =VLOOKUP(C27,'S4. Variable Importance'!A:M,5,FALSE) -> 30.881959 | B27: 23 | C27: Ramsar_count_p | D27: Social | E27: Conservation | F27: number of Ramsar sites / range area | G27: WDPA | H27: count / area | I27: #VALUE!
A28: =VLOOKUP(C28,'S4. Variable Importance'!A:M,5,FALSE) -> 30.373761 | B28: 24 | C28: bio_17 | D28: Environmental | E28: Climate | F28: Historic Precipitation of Driest Quarter | G28: Wordclim 2.1 - Historic | H28: mm | I28: #VALUE! | J28: roughly L-shaped, higest at 0, then drops and slowly rises to low asymptote ~350
A29: =VLOOKUP(C29,'S4. Variable Importance'!A:M,5,FALSE) -> 29.874429 | B29: 25 | C29: GDPslope | D29: Social | E29: Economy | F29: Avg. annual change in GDP | G29: World Bank | H29: Million Dollars | I29: #VALUE! | J29: highest at very low slopes | K29: endangerment associated with very low GDP slope
A30: =VLOOKUP(C30,'S4. Variable Importance'!A:M,5,FALSE) -> 28.705102 | B30: 26 | C30: PDslope | D30: Social | E30: Development | F30: Avg. annual change in population density 2000-2020 | G30: WorldPop | H30: Population/km2 | I30: #VALUE! | J30: roughly V-shaped but small variability, with highest risk at areas with negative population density trends, lowest risk with stable population density and increasing linearly above
A31: =VLOOKUP(C31,'S4. Variable Importance'!A:M,5,FALSE) -> 27.481786 | B31: 27 | C31: Reach_type | D31: Environmental | E31: Hydrology | F31: Mode of reach type (4 classes) | G31: GloRic | H31: categorical | I31: #VALUE! | J31: little variability, with subtly increased probabilities for classes 911, 311, and 1011 (very small rivers with low stream power). GloRiC key available at: https://data.hydrosheds.org/file/technical-documentation/GloRiC_TechDoc_v10.pdf
A32: =VLOOKUP(C32,'S4. Variable Importance'!A:M,5,FALSE) -> 27.237685 | B32: 28 | C32: LC_Grass | D32: Environmental | E32: Habitat | F32: Cover type percentage | G32: Copernicus - PROBA-V | H32: Percent | I32: #VALUE! | J32: slight initial drop, then increasing with increasing grass cover
A33: =VLOOKUP(C33,'S4. Variable Importance'!A:M,5,FALSE) -> 26.300557 | B33: 29 | C33: PDpercent | D33: Social | E33: Development | F33: Avg. annual percent change in population density | G33: WorldPop | H33: Percent Change | I33: #VALUE! | J33: roughly L shaped with small variability, highest risk at negative growth rates of population density, decreasing to lowest risk at 2.5% PD growth and slightly increasing above
A34: =VLOOKUP(C34,'S4. Variable Importance'!A:M,5,FALSE) -> 25.583506 | B34: 30 | C34: LC_Crops | D34: Social | E34: Development | F34: Cover type percentage | G34: Copernicus - PROBA-V | H34: Percent | I34: #VALUE! | J34: increasing with increasing crop landcover
A35: =VLOOKUP(C35,'S4. Variable Importance'!A:M,5,FALSE) -> 23.91271 | B35: 31 | C35: POP_SERVED_p | D35: Social | E35: Footprint | F35: human population wastewater service/area of species range | G35: HydroWASTE | H35: Population | I35: #VALUE!
A36: =VLOOKUP(C36,'S4. Variable Importance'!A:M,5,FALSE) -> 19.96813 | B36: 32 | C36: CAB_Dams_p | D36: Social | E36: Impoundments | F36: Total catchment areas blocked / area of species range | G36: GDW | H36: Proportion | I36: #VALUE! | J36: highest at 0, decreasing rapidly with asymptote at ~0.1 sqkm/sqkm
A37: =VLOOKUP(C37,'S4. Variable Importance'!A:M,5,FALSE) -> 19.8966 | B37: 33 | C37: Dams_p | D37: Social | E37: Impoundments | F37: Total existing large dams within range / range area | G37: GDW | H37: Count/km2 | I37: #VALUE! | J37: left-skewed V-shape, high near 0, dropping to lowest probability around 1e-10, and linear increase with higher dam densities
A38: =VLOOKUP(C38,'S4. Variable Importance'!A:M,5,FALSE) -> 17.534452 | B38: 34 | C38: RA_Dams_p | D38: Social | E38: Impoundments | F38: Total reservoir area in range / area of species range | G38: GDW | H38: Proportion | I38: #VALUE! | J38: highest at low values
A39: =VLOOKUP(C39,'S4. Variable Importance'!A:M,5,FALSE) -> 16.840625 | B39: 35 | C39: Extir_count | D39: Environmental | E39: Biotic | F39: count of extirpated species in range | G39: IUCN maps | H39: count | I39: #VALUE! | J39: highest at 0, then sharp decrease to ~0.5, then stable until 1.5 with a step incrase in probability | K39: could indicate tolerant species (less likely to be endangered if everything around you went extinct and you didn't)
A40: =VLOOKUP(C40,'S4. Variable Importance'!A:M,5,FALSE) -> 13.755861 | B40: 36 | C40: LC_Snow | D40: Environmental | E40: Hydrology | F40: Cover type percentage | G40: Copernicus - PROBA-V | H40: Percent | I40: #VALUE! | J40: inverted L shape with small probability range. Lowest probability at very low snow cover percents, rapidly increasing and stabilizing at highest risk over 2%. *PDP includes outliers
...

Sheet S6. GloRiC key
A1: GloRiC class index
A3: Hydrologic types
A5: Class number | B5: Flow regime variability (1st digit) | C5: Discharge average (2nd digit)
A6: 11 | B6: low variability | C6: very low discharge
A7: 12 | B7: low variability | C7: low discharge
A8: 13 | B8: low variability | C8: medium discharge
A9: 14 | B9: low variability | C9: high discharge
A10: 15 | B10: low variability | C10: very high discharge
A11: 21 | B11: medium variability | C11: very low discharge
A12: 22 | B12: medium variability | C12: low discharge
A13: 23 | B13: medium variability | C13: medium discharge
A14: 24 | B14: medium variability | C14: high discharge
A15: 25 | B15: medium variability | C15: very high discharge
A16: 31 | B16: high variability | C16: very low discharge
A17: 32 | B17: high variability | C17: low discharge
... A20: 35 | B20: high variability | C20: very high discharge
A22: Physioclimatic-types (Class_phys)
A24: Class number | B24: Minimum temprature (1st digit) | C24: CMI (2nd digit) | D24: Elevation (3rd digit)
A25: 111 | B25: low temperature | C25: low CMI | D25: low elevation
A26: 112 | B26: low temperature | C26: low CMI | D26: high elevation
A27: 121 | B27: low temperature | C27: medium CMI | D27: low elevation
A28: 122 | B28: low temperature | C28: medium CMI | D28: high elevation
A29: 131 | B29: low temperature | C29: high CMI | D29: low elevation
A30: 132 | B30: low temperature | C30: high CMI | D30: high elevation
A31: 211 | B31: medium temperature | C31: low CMI | D31: low elevation
A32: 212 | B32: medium temperature | C32: low CMI | D32: high elevation
A33: 221 | B33: medium temperature | C33: medium CMI | D33: low elevation
A34: 222 | B34: medium temperature | C34: medium CMI | D34: high elevation
A35: 231 | B35: medium temperature | C35: high CMI | D35: low elevation
A36: 232 | B36: medium temperature | C36: high CMI | D36: high elevation
... A48: 432 | B48: very high temperature | C48: high CMI | D48: high elevation
A51: Geomorphic types
A53: Class number | B53: Lake-wetland influence (1st digit) | C53: Stream power (2nd digit)
A54: 11 | B54: no lakes or wetlands | C54: low stream power
A55: 12 | B55: no lakes or wetlands | C55: high stream power
A56: 21 | B56: lake-wetland influenced | C56: low stream power
A57: 22 | B57: lake-wetland influenced | C57: high stream power
A59: River reach types
A61: Class number | B61: Reduced physio-climatic class (1st digit) | C61: Reduced hydrologic class (2nd digit) | D61: Reduced geomorphic class (3rd digit)
A62: 111 | B62: cold, low and medium moisture region | C62: very small river | D62: low stream power
...
